Workbook

Sheet Summary
A1: Sanatan app: image checklist
A2: Set "Done?" to Yes on each section sheet after the picture is made and uploaded in studio.html. Totals update automatically.
A4: Section | B4: Total | C4: Done | D4: Left | E4: % done
A5: A-Z Stories | B5: =COUNTA('A-Z Stories'!D2:D132) | C5: =COUNTIF('A-Z Stories'!B2:B132,"Yes") | D5: =B5-C5 | E5: =IF(B5=0,0,C5/B5)
A6: Gujarati Akshar | B6: =COUNTA('Gujarati Akshar'!D2:D48) | C6: =COUNTIF('Gujarati Akshar'!B2:B48,"Yes") | D6: =B6-C6 | E6: =IF(B6=0,0,C6/B6)
A7: Hindi Akshar | B7: =COUNTA('Hindi Akshar'!D2:D48) | C7: =COUNTIF('Hindi Akshar'!B2:B48,"Yes") | D7: =B7-C7 | E7: =IF(B7=0,0,C7/B7)
A8: Numbers | B8: =COUNTA('Numbers'!D2:D14) | C8: =COUNTIF('Numbers'!B2:B14,"Yes") | D8: =B8-C8 | E8: =IF(B8=0,0,C8/B8)
A9: Deities | B9: =COUNTA('Deities'!D2:D37) | C9: =COUNTIF('Deities'!B2:B37,"Yes") | D9: =B9-C9 | E9: =IF(B9=0,0,C9/B9)
A10: Dashavatar | B10: =COUNTA('Dashavatar'!D2:D31) | C10: =COUNTIF('Dashavatar'!B2:B31,"Yes") | D10: =B10-C10 | E10: =IF(B10=0,0,C10/B10)
A11: Total | B11: =SUM(B5:B10) | C11: =SUM(C5:C10) | D11: =SUM(D5:D10) | E11: =IF(B11=0,0,C11/B11)
A14: How to work
A15: 1. For scene stories, make scene 1 first and attach it as the reference for scenes 2, 3, ...
A16: 2. Copy the prompt from column F, paste into Google Flow / Gemini, generate the picture (16:9).
A17: 3. Upload it in studio.html (it saves as webp with the right name). Mark Done = Yes here.
A18: 4. Download the ZIP from studio.html and send it back.

Sheet A-Z Stories
A1: # | B1: Done? | C1: Label | D1: Save as (file name) | E1: Reference first? | F1: Prompt (copy into Google Flow / Gemini)
A2: 1 | B2: No | C2: A/1 — Arjun · curious-happy | D2: art/scenes/A/1.webp | F2: 3D animated cartoon style, like a Pixar-quality children's movie still: big expressive eyes, soft rounded shapes, warm cinematic lighting, rich saturated colours, vibrant Indian heritage setting (temples, forts, forests, palaces). Setting: sunny royal garden of the Hastinapur palace, marble pillars, lotus pond, peacocks walking by. Characters — Arjun: handsome Indian prince, medium-brown skin, large expressive dark eyes, curly shoulder-length black hair half tied up, small gold crown (mukut) with one peacock feather, golden-yellow dhoti with a maroon sash, gold armlets and a pearl necklace, carries the golden bow Gandiva decorated with peacock-feather patterns. As a child (age 8): same face, round cheeks, hair in a small topknot, simple yellow dhoti, a tiny wooden bow. Kunti: gentle royal mother, warm kind eyes, white and soft-pink saree with a gold border, a light veil over her head, simple gold jewellery. Action: child Arjun (age 8) proudly holds up his tiny wooden bow with an arrow, standing on tiptoe; Mother Kunti watches him from a garden bench with a loving smile. Expressions: bright wide smile, sparkling eyes full of dreams. Camera: wide establishing shot, eye level. Landscape 16:9, 2816x1536 px. NO text, NO captions, NO letters, NO watermark, no logo. Child-friendly: no blood, no gore, no frightening faces. Battle scenes show only calm tension, never violence.
A3: 2 | B3: No | C3: A/2 — Arjun · determined-respectful | D3: art/scenes/A/2.webp | E3: Use art/scenes/A/1.webp | F3: 3D animated cartoon style, like a Pixar-quality children's movie still: big expressive eyes, soft rounded shapes, warm cinematic lighting, rich saturated colours, vibrant Indian heritage setting (temples, forts, forests, palaces). Setting: open-air gurukul training ground at sunrise, a banyan tree, archery targets, other young princes practising in the soft background. Characters — Arjun: handsome Indian prince, medium-brown skin, large expressive dark eyes, curly shoulder-length black hair half tied up, small gold crown (mukut) with one peacock feather, golden-yellow dhoti with a maroon sash, gold armlets and a pearl necklace, carries the golden bow Gandiva decorated with peacock-feather patterns. As a child (age 8): same face, round cheeks, hair in a small topknot, simple yellow dhoti, a tiny wooden bow. Dronacharya: dignified elderly teacher, white beard and moustache, topknot, saffron robe with a white shawl, rudraksha beads, kind but stern eyes, holds a long bow. Action: teenage Arjun (age 14) bows respectfully with folded hands in front of Dronacharya, who places a blessing hand on his head. Expressions: Arjun: humble, eager eyes; Dronacharya: warm approving smile. Camera: medium two-shot, slightly low angle, golden sunrise rim light. Landscape 16:9, 2816x1536 px. NO text, NO captions, NO letters, NO watermark, no logo. Child-friendly: no blood, no gore, no frightening faces. Battle scenes show only calm tension, never violence. Keep each character's face, hair, clothes and colours EXACTLY the same as in scene 1 of this story (use the scene 1 image as the reference image for every later scene).
A4: 3 | B4: No | C4: A/3 — Arjun · laser-focus-triumphant | D4: art/scenes/A/3.webp | E4: Use art/scenes/A/1.webp | F4: 3D animated cartoon style, like a Pixar-quality children's movie still: big expressive eyes, soft rounded shapes, warm cinematic lighting, rich saturated colours, vibrant Indian heritage setting (temples, forts, forests, palaces). Setting: forest clearing, a tall tree with a small wooden bird on a far branch in sharp focus, other students blurred in the background, golden morning light. Characters — Arjun: handsome Indian prince, medium-brown skin, large expressive dark eyes, curly shoulder-length black hair half tied up, small gold crown (mukut) with one peacock feather, golden-yellow dhoti with a maroon sash, gold armlets and a pearl necklace, carries the golden bow Gandiva decorated with peacock-feather patterns. As a child (age 8): same face, round cheeks, hair in a small topknot, simple yellow dhoti, a tiny wooden bow. Dronacharya: dignified elderly teacher, white beard and moustache, topknot, saffron robe with a white shawl, rudraksha beads, kind but stern eyes, holds a long bow. Action: Arjun (age 14) draws his bow fully, arrow aimed at the wooden bird's eye; Dronacharya stands a little behind him watching. Expressions: Arjun: eyes narrowed, calm laser-sharp concentration; Dronacharya: proud, hopeful smile. Camera: close side-profile of Arjun's face and bow, shallow depth of field, the bird glowing in the distance. Landscape 16:9, 2816x1536 px. NO text, NO captions, NO letters, NO watermark, no logo. Child-friendly: no blood, no gore, no frightening faces. Battle scenes show only calm tension, never violence. Keep each character's face, hair, clothes and colours EXACTLY the same as in scene 1 of this story (use the scene 1 image as the reference image for every later scene).
A5: 4 | B5: No | C5: A/4 — Arjun · proud-confident | D5: art/scenes/A/4.webp | E5: Use art/scenes/A/1.webp | F5: 3D animated cartoon style, like a Pixar-quality children's movie still: big expressive eyes, soft rounded shapes, warm cinematic lighting, rich saturated colours, vibrant Indian heritage setting (temples, forts, forests, palaces). Setting: grand royal swayamvara hall of Panchala with golden pillars, flower garlands, cheering kings; a golden spinning fish target high above and a bowl of water below it. Characters — Arjun: handsome Indian prince, medium-brown skin, large expressive dark eyes, curly shoulder-length black hair half tied up, small gold crown (mukut) with one peacock feather, golden-yellow dhoti with a maroon sash, gold armlets and a pearl necklace, carries the golden bow Gandiva decorated with peacock-feather patterns. As a child (age 8): same face, round cheeks, hair in a small topknot, simple yellow dhoti, a tiny wooden bow. Draupadi: graceful princess in a red and gold bridal saree, long black hair with flowers, a flower garland in her hands, dignified calm smile. Action: young adult Arjun in a tall confident stance has just released an arrow upward, the arrow flying toward the spinning golden fish; Draupadi watches from the side holding a flower garland. Expressions: Arjun: calm confident smile; Draupadi: delighted wonder. Camera: low-angle heroic shot looking up toward the arrow and fish, sparkles in the air. Landscape 16:9, 2816x1536 px. NO text, NO captions, NO letters, NO watermark, no logo. Child-friendly: no blood, no gore, no frightening faces. Battle scenes show only calm tension, never violence. Keep each character's face, hair, clothes and colours EXACTLY the same as in scene 1 of this story (use the scene 1 image as the reference image for every later scene).
A6: 5 | B6: No | C6: A/5 — Arjun · sad-confused | D6: art/scenes/A/5.webp | E6: Use art/scenes/A/1.webp | F6: 3D animated cartoon style, like a Pixar-quality children's movie still: big expressive eyes, soft rounded shapes, warm cinematic lighting, rich saturated colours, vibrant Indian heritage setting (temples, forts, forests, palaces). Setting: the vast field of Kurukshetra at dawn under a hazy orange sky, two distant armies as calm silhouettes with banners, a grand golden chariot with four white horses in the foreground. Characters — Arjun: handsome Indian prince, medium-brown skin, large expressive dark eyes, curly shoulder-length black hair half tied up, small gold crown (mukut) with one peacock feather, golden-yellow dhoti with a maroon sash, gold armlets and a pearl necklace, carries the golden bow Gandiva decorated with peacock-feather patterns. As a child (age 8): same face, round cheeks, hair in a small topknot, simple yellow dhoti, a tiny wooden bow. Krishna: blue-skinned Lord Krishna, gentle smile, large lotus-shaped eyes, golden crown with a peacock feather, yellow pitambar dhoti, flower garland, gold ornaments, a bamboo flute. As a child (age 5): same face, round cheeks, small peacock feather, butter on his cheeks. As charioteer he holds the reins of four white horses. Action: Arjun sits down slumped on the chariot floor, his golden bow resting on the ground beside him; Krishna, the charioteer, turns toward him with a gentle caring look. Expressions: Arjun: sad, teary, lost; Krishna: calm, kind, reassuring. Camera: medium shot from the side of the chariot, soft misty light, no violence shown. Landscape 16:9, 2816x1536 px. NO text, NO captions, NO letters, NO watermark, no logo. Child-friendly: no blood, no gore, no frightening faces. Battle scenes show only calm tension, never violence. Keep each character's face, hair, clothes and colours EXACTLY the same as in scene 1 of this story (use the scene 1 image as the reference image for every later scene).
A7: 6 | B7: No | C7: A/6 — Arjun · inspired-resolute | D7: art/scenes/A/6.webp | E7: Use art/scenes/A/1.webp | F7: 3D animated cartoon style, like a Pixar-quality children's movie still: big expressive eyes, soft rounded shapes, warm cinematic lighting, rich saturated colours, vibrant Indian heritage setting (temples, forts, forests, palaces). Setting: the same Kurukshetra chariot, now with golden sunrise rays breaking through the clouds, a soft divine glow around the chariot. Characters — Arjun: handsome Indian prince, medium-brown skin, large expressive dark eyes, curly shoulder-length black hair half tied up, small gold crown (mukut) with one peacock feather, golden-yellow dhoti with a maroon sash, gold armlets and a pearl necklace, carries the golden bow Gandiva decorated with peacock-feather patterns. As a child (age 8): same face, round cheeks, hair in a small topknot, simple yellow dhoti, a tiny wooden bow. Krishna: blue-skinned Lord Krishna, gentle smile, large lotus-shaped eyes, golden crown with a peacock feather, yellow pitambar dhoti, flower garland, gold ornaments, a bamboo flute. As a child (age 5): same face, round cheeks, small peacock feather, butter on his cheeks. As charioteer he holds the reins of four white horses. Action: Krishna points gently toward the sky while speaking; Arjun stands tall in the chariot lifting his golden Gandiva bow again with a firm grip. Expressions: Arjun: calm, bright, determined; Krishna: loving, wise smile. Camera: heroic wide shot from slightly below, warm glowing light, golden dust sparkles. Landscape 16:9, 2816x1536 px. NO text, NO captions, NO letters, NO watermark, no logo. Child-friendly: no blood, no gore, no frightening faces. Battle scenes show only calm tension, never violence. Keep each character's face, hair, clothes and colours EXACTLY the same as in scene 1 of this story (use the scene 1 image as the reference image for every later scene).
A8: 7 | B8: No | C8: B/1 — Bhishma Pitamah · proud-happy | D8: art/scenes/B/1.webp | F8: 3D animated cartoon style, like a Pixar-quality children's movie still: big expressive eyes, soft rounded shapes, warm cinematic lighting, rich saturated colours, vibrant Indian heritage setting (temples, forts, forests, palaces). Setting: royal palace of Hastinapur, grand courtyard with marble pillars and a river view, morning light. Characters — Bhishma Pitamah: tall majestic elderly warrior-sage, long white beard and white hair, maroon and gold armour with a white shawl, a long bow, calm noble face. As a young prince Devavrata (age 16): same face without beard, black hair, simple royal clothes. Action: young prince Devavrata (age 16) proudly practises with a bow in the courtyard while King Shantanu watches lovingly from a balcony. Expressions: Devavrata: bright, confident smile; King Shantanu: proud and loving. Camera: wide shot, slightly low angle. Landscape 16:9, 2816x1536 px. NO text, NO captions, NO letters, NO watermark, no logo. Child-friendly: no blood, no gore, no frightening faces. Battle scenes show only calm tension, never violence.
A9: 8 | B9: No | C9: B/2 — Bhishma Pitamah · thoughtful-caring | D9: art/scenes/B/2.webp | E9: Use art/scenes/B/1.webp | F9: 3D animated cartoon style, like a Pixar-quality children's movie still: big expressive eyes, soft rounded shapes, warm cinematic lighting, rich saturated colours, vibrant Indian heritage setting (temples, forts, forests, palaces). Setting: a peaceful river bank in the evening with fishing boats, and the palace far away. Characters — Bhishma Pitamah: tall majestic elderly warrior-sage, long white beard and white hair, maroon and gold armour with a white shawl, a long bow, calm noble face. As a young prince Devavrata (age 16): same face without beard, black hair, simple royal clothes. Action: Devavrata gently asks his sad father what is wrong; Shantanu looks down at the river; the fisher-chief and Satyavati wait in the background. Expressions: Devavrata: caring, concerned; Shantanu: quietly sad. Camera: medium shot at eye level, soft evening light. Landscape 16:9, 2816x1536 px. NO text, NO captions, NO letters, NO watermark, no logo. Child-friendly: no blood, no gore, no frightening faces. Battle scenes show only calm tension, never violence. Keep each character's face, hair, clothes and colours EXACTLY the same as in scene 1 of this story (use the scene 1 image as the reference image for every later scene).
A10: 9 | B10: No | C10: B/3 — Bhishma Pitamah · noble-resolute | D10: art/scenes/B/3.webp | E10: Use art/scenes/B/1.webp | F10: 3D animated cartoon style, like a Pixar-quality children's movie still: big expressive eyes, soft rounded shapes, warm cinematic lighting, rich saturated colours, vibrant Indian heritage setting (temples, forts, forests, palaces). Setting: a riverside court gathering under a big tree, flower petals falling from the sky, golden afternoon light. Characters — Bhishma Pitamah: tall majestic elderly warrior-sage, long white beard and white hair, maroon and gold armour with a white shawl, a long bow, calm noble face. As a young prince Devavrata (age 16): same face without beard, black hair, simple royal clothes. Action: Devavrata stands tall with one hand raised in promise, while onlookers gasp and flower petals fall from above. Expressions: Devavrata: calm, firm and selfless; onlookers: amazed. Camera: heroic low-angle medium shot, falling petals in the foreground. Landscape 16:9, 2816x1536 px. NO text, NO captions, NO letters, NO watermark, no logo. Child-friendly: no blood, no gore, no frightening faces. Battle scenes show only calm tension, never violence. Keep each character's face, hair, clothes and colours EXACTLY the same as in scene 1 of this story (use the scene 1 image as the reference image for every later scene).
A11: 10 | B11: No | C11: B/4 — Bhishma Pitamah · peaceful-protective | D11: art/scenes/B/4.webp | E11: Use art/scenes/B/1.webp | F11: 3D animated cartoon style, like a Pixar-quality children's movie still: big expressive eyes, soft rounded shapes, warm cinematic lighting, rich saturated colours, vibrant Indian heritage setting (temples, forts, forests, palaces). Setting: Hastinapur royal courtyard in the morning, young Pandava and Kaurava princes playing around. Characters — Bhishma Pitamah: tall majestic elderly warrior-sage, long white beard and white hair, maroon and gold armour with a white shawl, a long bow, calm noble face. As a young prince Devavrata (age 16): same face without beard, black hair, simple royal clothes. Action: elderly Bhishma with a white beard smilingly watches the children and gently places a hand on a small prince's shoulder. Expressions: Bhishma: warm, wise, protective smile; children: happy. Camera: medium shot with warm morning backlight. Landscape 16:9, 2816x1536 px. NO text, NO captions, NO letters, NO watermark, no logo. Child-friendly: no blood, no gore, no frightening faces. Battle scenes show only calm tension, never violence. Keep each character's face, hair, clothes and colours EXACTLY the same as in scene 1 of this story (use the scene 1 image as the reference image for every later scene).
A12: 11 | B12: No | C12: B/5 — Bhishma Pitamah · serene-wise | D12: art/scenes/B/5.webp | E12: Use art/scenes/B/1.webp | F12: 3D animated cartoon style, like a Pixar-quality children's movie still: big expressive eyes, soft rounded shapes, warm cinematic lighting, rich saturated colours, vibrant Indian heritage setting (temples, forts, forests, palaces). Setting: a quiet field at sunrise, Bhishma resting on a soft bed with a white shawl, a few arrows stuck harmlessly in the ground around as a calm symbol, warm golden light, no blood. Characters — Bhishma Pitamah: tall majestic elderly warrior-sage, long white beard and white hair, maroon and gold armour with a white shawl, a long bow, calm noble face. As a young prince Devavrata (age 16): same face without beard, black hair, simple royal clothes. Yudhishthira: tall calm king, medium-brown skin, simple white and gold royal robes, modest gold crown, kind truthful eyes, a gentle smile. Action: Bhishma speaks gently while Yudhishthira and the four brothers sit around him with folded hands, listening. Expressions: Bhishma: peaceful, wise, loving; Pandavas: respectful, attentive. Camera: wide gentle shot with sun rays. Landscape 16:9, 2816x1536 px. NO text, NO captions, NO letters, NO watermark, no logo. Child-friendly: no blood, no gore, no frightening faces. Battle scenes show only calm tension, never violence. Keep each character's face, hair, clothes and colours EXACTLY the same as in scene 1 of this story (use the scene 1 image as the reference image for every later scene).
A13: 12 | B13: No | C13: C/1 — Chanakya · curious-wise | D13: art/scenes/C/1.webp | F13: 3D animated cartoon style, like a Pixar-quality children's movie still: big expressive eyes, soft rounded shapes, warm cinematic lighting, rich saturated colours, vibrant Indian heritage setting (temples, forts, forests, palaces). Setting: ancient Takshashila university campus with stone buildings, banyan trees and students sitting on the ground with palm-leaf books, golden morning light. Characters — Chanakya: thin wise scholar-teacher, shaved head with a long topknot (shikha), white dhoti and shawl, sharp kind eyes, holds a palm-leaf manuscript. Action: Chanakya stands in front of a group of attentive students, holding a palm-leaf manuscript and explaining with one hand raised. Expressions: Chanakya: wise, sharp and kind; students: curious. Camera: wide establishing shot, eye level. Landscape 16:9, 2816x1536 px. NO text, NO captions, NO letters, NO watermark, no logo. Child-friendly: no blood, no gore, no frightening faces. Battle scenes show only calm tension, never violence.
A14: 13 | B14: No | C14: C/2 — Chanakya · determined-patriotic | D14: art/scenes/C/2.webp | E14: Use art/scenes/C/1.webp | F14: 3D animated cartoon style, like a Pixar-quality children's movie still: big expressive eyes, soft rounded shapes, warm cinematic lighting, rich saturated colours, vibrant Indian heritage setting (temples, forts, forests, palaces). Setting: a simple hut at the edge of a village at dusk, a lamp glowing, a map drawn on the ground, hills in the distance. Characters — Chanakya: thin wise scholar-teacher, shaved head with a long topknot (shikha), white dhoti and shawl, sharp kind eyes, holds a palm-leaf manuscript. Action: Chanakya sits thoughtfully looking at a map drawn on the ground and then lifts his eyes toward the horizon. Expressions: Chanakya: deep thought, quiet determination. Camera: medium shot, warm lamp light on his face. Landscape 16:9, 2816x1536 px. NO text, NO captions, NO letters, NO watermark, no logo. Child-friendly: no blood, no gore, no frightening faces. Battle scenes show only calm tension, never violence. Keep each character's face, hair, clothes and colours EXACTLY the same as in scene 1 of this story (use the scene 1 image as the reference image for every later scene).
A15: 14 | B15: No | C15: C/3 — Chanakya · discovering-hopeful | D15: art/scenes/C/3.webp | E15: Use art/scenes/C/1.webp | F15: 3D animated cartoon style, like a Pixar-quality children's movie still: big expressive eyes, soft rounded shapes, warm cinematic lighting, rich saturated colours, vibrant Indian heritage setting (temples, forts, forests, palaces). Setting: a village field with a mango tree, children playing a game of court with sticks and stones, golden afternoon light. Characters — Chanakya: thin wise scholar-teacher, shaved head with a long topknot (shikha), white dhoti and shawl, sharp kind eyes, holds a palm-leaf manuscript. Action: Chanakya watches from the edge of the field with a smile while a bright boy (Chandragupta, age 10, simple clothes, a crown made of leaves) sits on a rock like a king giving judgement to other children. Expressions: Chanakya: pleasantly surprised; Chandragupta: confident and fair; children: giggling. Camera: medium-wide shot, shallow depth of field. Landscape 16:9, 2816x1536 px. NO text, NO captions, NO letters, NO watermark, no logo. Child-friendly: no blood, no gore, no frightening faces. Battle scenes show only calm tension, never violence. Keep each character's face, hair, clothes and colours EXACTLY the same as in scene 1 of this story (use the scene 1 image as the reference image for every later scene).
A16: 15 | B16: No | C16: C/4 — Chanakya · proud-teaching | D16: art/scenes/C/4.webp | E16: Use art/scenes/C/1.webp | F16: 3D animated cartoon style, like a Pixar-quality children's movie still: big expressive eyes, soft rounded shapes, warm cinematic lighting, rich saturated colours, vibrant Indian heritage setting (temples, forts, forests, palaces). Setting: a grand royal court of Magadha with golden pillars, flags and citizens gathered, bright daylight. Characters — Chanakya: thin wise scholar-teacher, shaved head with a long topknot (shikha), white dhoti and shawl, sharp kind eyes, holds a palm-leaf manuscript. Action: young emperor Chandragupta (age 22, gold crown, royal clothes) sits on the throne and bows slightly to Chanakya who stands beside him with folded hands, a happy crowd around. Expressions: Chandragupta: respectful and proud; Chanakya: quietly satisfied. Camera: wide celebratory shot with warm light. Landscape 16:9, 2816x1536 px. NO text, NO captions, NO letters, NO watermark, no logo. Child-friendly: no blood, no gore, no frightening faces. Battle scenes show only calm tension, never violence. Keep each character's face, hair, clothes and colours EXACTLY the same as in scene 1 of this story (use the scene 1 image as the reference image for every later scene).
A17: 16 | B17: No | C17: C/5 — Chanakya · humble-wise | D17: art/scenes/C/5.webp | E17: Use art/scenes/C/1.webp | F17: 3D animated cartoon style, like a Pixar-quality children's movie still: big expressive eyes, soft rounded shapes, warm cinematic lighting, rich saturated colours, vibrant Indian heritage setting (temples, forts, forests, palaces). Setting: a modest forest hut with a lamp, many palm-leaf manuscripts stacked, a river outside in the evening glow. Characters — Chanakya: thin wise scholar-teacher, shaved head with a long topknot (shikha), white dhoti and shawl, sharp kind eyes, holds a palm-leaf manuscript. Action: Chanakya sits on a mat writing with a reed pen on a palm-leaf; young students sit near him listening. Expressions: Chanakya: peaceful, contented, wise. Camera: medium shot, warm lamp light. Landscape 16:9, 2816x1536 px. NO text, NO captions, NO letters, NO watermark, no logo. Child-friendly: no blood, no gore, no frightening faces. Battle scenes show only calm tension, never violence. Keep each character's face, hair, clothes and colours EXACTLY the same as in scene 1 of this story (use the scene 1 image as the reference image for every later scene).
A18: 17 | B18: No | C18: D/1 — Dronacharya · humble-loving | D18: art/scenes/D/1.webp | F18: 3D animated cartoon style, like a Pixar-quality children's movie still: big expressive eyes, soft rounded shapes, warm cinematic lighting, rich saturated colours, vibrant Indian heritage setting (temples, forts, forests, palaces). Setting: a simple hermitage hut in a green forest, a cow and a fire pit outside, soft morning mist. Characters — Dronacharya: dignified elderly teacher, white beard and moustache, topknot, saffron robe with a white shawl, rudraksha beads, kind but stern eyes, holds a long bow. Action: Dronacharya (younger, black beard streaked with grey) sits outside the hut and holds his little son Ashwatthama (age 5) on his lap, both smiling. Expressions: Dronacharya: gentle and loving; child: giggling. Camera: warm medium shot with misty forest behind. Landscape 16:9, 2816x1536 px. NO text, NO captions, NO letters, NO watermark, no logo. Child-friendly: no blood, no gore, no frightening faces. Battle scenes show only calm tension, never violence.
A19: 18 | B19: No | C19: D/2 — Dronacharya · playful-amazed | D19: art/scenes/D/2.webp | E19: Use art/scenes/D/1.webp | F19: 3D animated cartoon style, like a Pixar-quality children's movie still: big expressive eyes, soft rounded shapes, warm cinematic lighting, rich saturated colours, vibrant Indian heritage setting (temples, forts, forests, palaces). Setting: a garden with an old stone well under a big tree outside Hastinapur, bright afternoon. Characters — Dronacharya: dignified elderly teacher, white beard and moustache, topknot, saffron robe with a white shawl, rudraksha beads, kind but stern eyes, holds a long bow. Action: Dronacharya holds a bow and has shot a chain of arrows joined together into the well; a small ball floats up on the last arrow while young princes (Kaurava and Pandava boys) crowd around with open mouths. Expressions: Dronacharya: calm and slightly amused; princes: wide-eyed amazement. Camera: medium-wide shot at the well, sunlight through leaves. Landscape 16:9, 2816x1536 px. NO text, NO captions, NO letters, NO watermark, no logo. Child-friendly: no blood, no gore, no frightening faces. Battle scenes show only calm tension, never violence. Keep each character's face, hair, clothes and colours EXACTLY the same as in scene 1 of this story (use the scene 1 image as the reference image for every later scene).
A20: 19 | B20: No | C20: D/3 — Dronacharya · respected-honoured | D20: art/scenes/D/3.webp | E20: Use art/scenes/D/1.webp | F20: 3D animated cartoon style, like a Pixar-quality children's movie still: big expressive eyes, soft rounded shapes, warm cinematic lighting, rich saturated colours, vibrant Indian heritage setting (temples, forts, forests, palaces). Setting: royal hall of Hastinapur with golden pillars, morning light through arches. Characters — Dronacharya: dignified elderly teacher, white beard and moustache, topknot, saffron robe with a white shawl, rudraksha beads, kind but stern eyes, holds a long bow. Bhishma Pitamah: tall majestic elderly warrior-sage, long white beard and white hair, maroon and gold armour with a white shawl, a long bow, calm noble face. As a young prince Devavrata (age 16): same face without beard, black hair, simple royal clothes. Action: Bhishma, white-bearded, folds his hands and welcomes Dronacharya, who bows slightly; a few little princes smile behind them. Expressions: Bhishma: respectful, pleased; Dronacharya: humble gratitude. Camera: medium two-shot, warm light. Landscape 16:9, 2816x1536 px. NO text, NO captions, NO letters, NO watermark, no logo. Child-friendly: no blood, no gore, no frightening faces. Battle scenes show only calm tension, never violence. Keep each character's face, hair, clothes and colours EXACTLY the same as in scene 1 of this story (use the scene 1 image as the reference image for every later scene).
A21: 20 | B21: No | C21: D/4 — Dronacharya · teaching-disciplined | D21: art/scenes/D/4.webp | E21: Use art/scenes/D/1.webp | F21: 3D animated cartoon style, like a Pixar-quality children's movie still: big expressive eyes, soft rounded shapes, warm cinematic lighting, rich saturated colours, vibrant Indian heritage setting (temples, forts, forests, palaces). Setting: a large open training ground with straw targets and flags at sunrise. Characters — Dronacharya: dignified elderly teacher, white beard and moustache, topknot, saffron robe with a white shawl, rudraksha beads, kind but stern eyes, holds a long bow. Arjun: handsome Indian prince, medium-brown skin, large expressive dark eyes, curly shoulder-length black hair half tied up, small gold crown (mukut) with one peacock feather, golden-yellow dhoti with a maroon sash, gold armlets and a pearl necklace, carries the golden bow Gandiva decorated with peacock-feather patterns. As a child (age 8): same face, round cheeks, hair in a small topknot, simple yellow dhoti, a tiny wooden bow. Action: Dronacharya corrects a young prince's grip on the bow while Arjun (age 14) practises beside them and other princes train in rows. Expressions: Dronacharya: patient, stern but caring; Arjun: focused. Camera: wide training-ground shot, dust glowing in the sunlight. Landscape 16:9, 2816x1536 px. NO text, NO captions, NO letters, NO watermark, no logo. Child-friendly: no blood, no gore, no frightening faces. Battle scenes show only calm tension, never violence. Keep each character's face, hair, clothes and colours EXACTLY the same as in scene 1 of this story (use the scene 1 image as the reference image for every later scene).
A22: 21 | B22: No | C22: D/5 — Dronacharya · grateful-respectful | D22: art/scenes/D/5.webp | E22: Use art/scenes/D/1.webp | F22: 3D animated cartoon style, like a Pixar-quality children's movie still: big expressive eyes, soft rounded shapes, warm cinematic lighting, rich saturated colours, vibrant Indian heritage setting (temples, forts, forests, palaces). Setting: a peaceful gurukul courtyard in the evening, oil lamps lit, flower petals on the ground. Characters — Dronacharya: dignified elderly teacher, white beard and moustache, topknot, saffron robe with a white shawl, rudraksha beads, kind but stern eyes, holds a long bow. Arjun: handsome Indian prince, medium-brown skin, large expressive dark eyes, curly shoulder-length black hair half tied up, small gold crown (mukut) with one peacock feather, golden-yellow dhoti with a maroon sash, gold armlets and a pearl necklace, carries the golden bow Gandiva decorated with peacock-feather patterns. As a child (age 8): same face, round cheeks, hair in a small topknot, simple yellow dhoti, a tiny wooden bow. Action: students including Arjun offer flowers and bow to Dronacharya, who blesses them with a raised hand. Expressions: students: devoted joy; Dronacharya: proud and blessing smile. Camera: medium shot, soft lamp glow. Landscape 16:9, 2816x1536 px. NO text, NO captions, NO letters, NO watermark, no logo. Child-friendly: no blood, no gore, no frightening faces. Battle scenes show only calm tension, never violence. Keep each character's face, hair, clothes and colours EXACTLY the same as in scene 1 of this story (use the scene 1 image as the reference image for every later scene).
A23: 22 | B23: No | C23: E/1 — Eklavya · eager-hopeful | D23: art/scenes/E/1.webp | F23: 3D animated cartoon style, like a Pixar-quality children's movie still: big expressive eyes, soft rounded shapes, warm cinematic lighting, rich saturated colours, vibrant Indian heritage setting (temples, forts, forests, palaces). Setting: a green forest path with sun rays, tall trees, small tribal huts in the distance. Characters — Eklavya: young tribal forest prince (age 14), dark skin, thick black hair tied with a green headband, simple forest clothes with feather ornaments, a handmade wooden bow, determined face. Action: Eklavya walks eagerly along the forest path carrying his bow, looking toward the far-away city. Expressions: bright hopeful eyes, determined smile. Camera: wide shot following him from the side. Landscape 16:9, 2816x1536 px. NO text, NO captions, NO letters, NO watermark, no logo. Child-friendly: no blood, no gore, no frightening faces. Battle scenes show only calm tension, never violence.
A24: 23 | B24: No | C24: E/2 — Eklavya · disappointed-brave | D24: art/scenes/E/2.webp | E24: Use art/scenes/E/1.webp | F24: 3D animated cartoon style, like a Pixar-quality children's movie still: big expressive eyes, soft rounded shapes, warm cinematic lighting, rich saturated colours, vibrant Indian heritage setting (temples, forts, forests, palaces). Setting: the edge of the Hastinapur training ground at dusk. Characters — Eklavya: young tribal forest prince (age 14), dark skin, thick black hair tied with a green headband, simple forest clothes with feather ornaments, a handmade wooden bow, determined face. Dronacharya: dignified elderly teacher, white beard and moustache, topknot, saffron robe with a white shawl, rudraksha beads, kind but stern eyes, holds a long bow. Action: Eklavya bows with folded hands to Dronacharya, who looks at him with a kind but regretful face; Eklavya then turns to leave. Expressions: Eklavya: sad but respectful; Dronacharya: regretful. Camera: medium shot with long evening shadows. Landscape 16:9, 2816x1536 px. NO text, NO captions, NO letters, NO watermark, no logo. Child-friendly: no blood, no gore, no frightening faces. Battle scenes show only calm tension, never violence. Keep each character's face, hair, clothes and colours EXACTLY the same as in scene 1 of this story (use the scene 1 image as the reference image for every later scene).
A25: 24 | B25: No | C25: E/3 — Eklavya · devoted-determined | D25: art/scenes/E/3.webp | E25: Use art/scenes/E/1.webp | F25: 3D animated cartoon style, like a Pixar-quality children's movie still: big expressive eyes, soft rounded shapes, warm cinematic lighting, rich saturated colours, vibrant Indian heritage setting (temples, forts, forests, palaces). Setting: a quiet forest clearing with a clay statue of an old teacher under a tree, wildflowers, soft golden morning light. Characters — Eklavya: young tribal forest prince (age 14), dark skin, thick black hair tied with a green headband, simple forest clothes with feather ornaments, a handmade wooden bow, determined face. Action: Eklavya aims his bow at a far target, with the clay statue of Dronacharya standing behind him; a garland of wild flowers hangs around the statue. Expressions: Eklavya: deep concentration and devotion. Camera: medium shot from behind-left showing statue and target. Landscape 16:9, 2816x1536 px. NO text, NO captions, NO letters, NO watermark, no logo. Child-friendly: no blood, no gore, no frightening faces. Battle scenes show only calm tension, never violence. Keep each character's face, hair, clothes and colours EXACTLY the same as in scene 1 of this story (use the scene 1 image as the reference image for every later scene).
A26: 25 | B26: No | C26: E/4 — Eklavya · skilful-proud | D26: art/scenes/E/4.webp | E26: Use art/scenes/E/1.webp | F26: 3D animated cartoon style, like a Pixar-quality children's movie still: big expressive eyes, soft rounded shapes, warm cinematic lighting, rich saturated colours, vibrant Indian heritage setting (temples, forts, forests, palaces). Setting: a forest clearing, a little dog sitting calmly with arrows around its mouth like a harmless frame, dappled sunlight. Characters — Eklavya: young tribal forest prince (age 14), dark skin, thick black hair tied with a green headband, simple forest clothes with feather ornaments, a handmade wooden bow, determined face. Arjun: handsome Indian prince, medium-brown skin, large expressive dark eyes, curly shoulder-length black hair half tied up, small gold crown (mukut) with one peacock feather, golden-yellow dhoti with a maroon sash, gold armlets and a pearl necklace, carries the golden bow Gandiva decorated with peacock-feather patterns. As a child (age 8): same face, round cheeks, hair in a small topknot, simple yellow dhoti, a tiny wooden bow. Dronacharya: dignified elderly teacher, white beard and moustache, topknot, saffron robe with a white shawl, rudraksha beads, kind but stern eyes, holds a long bow. Action: Arjun and Dronacharya stand at the edge of the clearing looking at the dog and then at Eklavya, who lowers his bow. Expressions: Arjun and Dronacharya: wide-eyed wonder; Eklavya: humble calm. Camera: wide shot from the clearing edge. Landscape 16:9, 2816x1536 px. NO text, NO captions, NO letters, NO watermark, no logo. Child-friendly: no blood, no gore, no frightening faces. Battle scenes show only calm tension, never violence. Keep each character's face, hair, clothes and colours EXACTLY the same as in scene 1 of this story (use the scene 1 image as the reference image for every later scene).
A27: 26 | B27: No | C27: E/5 — Eklavya · noble-giving | D27: art/scenes/E/5.webp | E27: Use art/scenes/E/1.webp | F27: 3D animated cartoon style, like a Pixar-quality children's movie still: big expressive eyes, soft rounded shapes, warm cinematic lighting, rich saturated colours, vibrant Indian heritage setting (temples, forts, forests, palaces). Setting: a forest clearing at sunset with the clay statue behind them, warm orange light. Characters — Eklavya: young tribal forest prince (age 14), dark skin, thick black hair tied with a green headband, simple forest clothes with feather ornaments, a handmade wooden bow, determined face. Dronacharya: dignified elderly teacher, white beard and moustache, topknot, saffron robe with a white shawl, rudraksha beads, kind but stern eyes, holds a long bow. Action: Eklavya kneels respectfully before Dronacharya with folded hands, offering his right hand; Dronacharya looks moved and sorry (no blood, no injury shown). Expressions: Eklavya: serene, devoted; Dronacharya: deeply moved. Camera: gentle medium shot, golden-hour glow. Landscape 16:9, 2816x1536 px. NO text, NO captions, NO letters, NO watermark, no logo. Child-friendly: no blood, no gore, no frightening faces. Battle scenes show only calm tension, never violence. Keep each character's face, hair, clothes and colours EXACTLY the same as in scene 1 of this story (use the scene 1 image as the reference image for every later scene).
A28: 27 | B28: No | C28: F/1 — Shabari · calm-devoted | D28: art/scenes/F/1.webp | F28: 3D animated cartoon style, like a Pixar-quality children's movie still: big expressive eyes, soft rounded shapes, warm cinematic lighting, rich saturated colours, vibrant Indian heritage setting (temples, forts, forests, palaces). Setting: a peaceful forest hermitage with small leaf huts, a sacred fire, tall trees and birds. Characters — Shabari: very old tribal woman, white hair in a bun, wrinkled kind face, simple saffron-brown saree, a leaf basket of berries, glowing devoted smile. Action: young Shabari sweeps the hermitage yard with a broom and smiles while the sage Matanga (white beard, saffron robes) watches kindly from the hut door. Expressions: Shabari: cheerful devotion; Matanga: gentle, blessing. Camera: wide gentle shot, morning light. Landscape 16:9, 2816x1536 px. NO text, NO captions, NO letters, NO watermark, no logo. Child-friendly: no blood, no gore, no frightening faces. Battle scenes show only calm tension, never violence.
A29: 28 | B29: No | C29: F/2 — Shabari · hopeful-joyful | D29: art/scenes/F/2.webp | E29: Use art/scenes/F/1.webp | F29: 3D animated cartoon style, like a Pixar-quality children's movie still: big expressive eyes, soft rounded shapes, warm cinematic lighting, rich saturated colours, vibrant Indian heritage setting (temples, forts, forests, palaces). Setting: the hermitage hut at sunset, golden light, a small lamp lit near the door. Characters — Shabari: very old tribal woman, white hair in a bun, wrinkled kind face, simple saffron-brown saree, a leaf basket of berries, glowing devoted smile. Action: old sage Matanga lovingly places his hand in blessing on Shabari's head while she folds her hands, eyes sparkling. Expressions: Shabari: tearful joy; Matanga: loving, peaceful. Camera: medium shot, warm sunset glow. Landscape 16:9, 2816x1536 px. NO text, NO captions, NO letters, NO watermark, no logo. Child-friendly: no blood, no gore, no frightening faces. Battle scenes show only calm tension, never violence. Keep each character's face, hair, clothes and colours EXACTLY the same as in scene 1 of this story (use the scene 1 image as the reference image for every later scene).
A30: 29 | B30: No | C30: F/3 — Shabari · patient-steady | D30: art/scenes/F/3.webp | E30: Use art/scenes/F/1.webp | F30: 3D animated cartoon style, like a Pixar-quality children's movie still: big expressive eyes, soft rounded shapes, warm cinematic lighting, rich saturated colours, vibrant Indian heritage setting (temples, forts, forests, palaces). Setting: a forest path in four moods of the day: sunrise light, flowers on both sides, a hut at the end, falling leaves showing the passing seasons. Characters — Shabari: very old tribal woman, white hair in a bun, wrinkled kind face, simple saffron-brown saree, a leaf basket of berries, glowing devoted smile. Action: old Shabari carefully sweeps the path with a broom and arranges fresh flowers by the door, looking hopefully down the path. Expressions: hopeful, patient, glowing. Camera: wide shot along the path with soft depth. Landscape 16:9, 2816x1536 px. NO text, NO captions, NO letters, NO watermark, no logo. Child-friendly: no blood, no gore, no frightening faces. Battle scenes show only calm tension, never violence. Keep each character's face, hair, clothes and colours EXACTLY the same as in scene 1 of this story (use the scene 1 image as the reference image for every later scene).
A31: 30 | B31: No | C31: F/4 — Shabari · overjoyed-loving | D31: art/scenes/F/4.webp | E31: Use art/scenes/F/1.webp | F31: 3D animated cartoon style, like a Pixar-quality children's movie still: big expressive eyes, soft rounded shapes, warm cinematic lighting, rich saturated colours, vibrant Indian heritage setting (temples, forts, forests, palaces). Setting: Shabari's leaf hut in a green forest, a leaf plate of red berries in the foreground, golden light. Characters — Shabari: very old tribal woman, white hair in a bun, wrinkled kind face, simple saffron-brown saree, a leaf basket of berries, glowing devoted smile. Ram: blue-skinned Lord Ram, calm gentle smile, golden crown, saffron-yellow dhoti, a long bow, noble face. During exile: matted hair topknot and simple bark-cloth clothes. Laxman: young prince with golden-brown skin, hair in a topknot, simple yellow-green forest robes, a bow and quiver, alert loyal eyes. Action: Ram and Laxman sit on a mat while old Shabari happily offers berries on a leaf plate. Expressions: Shabari: tearful bliss; Ram: loving smile; Laxman: curious and warm. Camera: medium close-up of the three with berries in sharp focus. Landscape 16:9, 2816x1536 px. NO text, NO captions, NO letters, NO watermark, no logo. Child-friendly: no blood, no gore, no frightening faces. Battle scenes show only calm tension, never violence. Keep each character's face, hair, clothes and colours EXACTLY the same as in scene 1 of this story (use the scene 1 image as the reference image for every later scene).
A32: 31 | B32: No | C32: F/5 — Shabari · tender-blessed | D32: art/scenes/F/5.webp | E32: Use art/scenes/F/1.webp | F32: 3D animated cartoon style, like a Pixar-quality children's movie still: big expressive eyes, soft rounded shapes, warm cinematic lighting, rich saturated colours, vibrant Indian heritage setting (temples, forts, forests, palaces). Setting: the same hut at golden sunset with warm light, a few petals falling. Characters — Shabari: very old tribal woman, white hair in a bun, wrinkled kind face, simple saffron-brown saree, a leaf basket of berries, glowing devoted smile. Ram: blue-skinned Lord Ram, calm gentle smile, golden crown, saffron-yellow dhoti, a long bow, noble face. During exile: matted hair topknot and simple bark-cloth clothes. Action: Ram eats a berry with a joyful smile and raises his other hand in blessing over Shabari, who bows with folded hands. Expressions: Ram: tender and happy; Shabari: radiant peace. Camera: gentle medium shot with warm backlight. Landscape 16:9, 2816x1536 px. NO text, NO captions, NO letters, NO watermark, no logo. Child-friendly: no blood, no gore, no frightening faces. Battle scenes show only calm tension, never violence. Keep each character's face, hair, clothes and colours EXACTLY the same as in scene 1 of this story (use the scene 1 image as the reference image for every later scene).
A33: 32 | B33: No | C33: G/1 — Ganesh · warm-loving | D33: art/scenes/G/1.webp | F33: 3D animated cartoon style, like a Pixar-quality children's movie still: big expressive eyes, soft rounded shapes, warm cinematic lighting, rich saturated colours, vibrant Indian heritage setting (temples, forts, forests, palaces). Setting: Mount Kailash palace garden with snow peaks and flowers, soft morning light. Characters — Uma (Parvati): Goddess Parvati (Uma), fair golden-brown skin, red saree with a gold border, crown and flowers, a small bindi, peaceful loving face. Ganesh: child-friendly Lord Ganesh, elephant head with one tusk, big kind eyes, red-and-yellow dhoti, golden crown, round belly, four arms holding a modak, an axe, a lotus and a blessing hand, a small friendly mouse nearby. Action: Goddess Parvati lovingly shapes a small boy from golden turmeric paste in her hands, a gentle glow giving the boy life. Expressions: Parvati: tender and loving; baby Ganesh: opening his eyes with a happy smile. Camera: close warm medium shot, golden glow. Landscape 16:9, 2816x1536 px. NO text, NO captions, NO letters, NO watermark, no logo. Child-friendly: no blood, no gore, no frightening faces. Battle scenes show only calm tension, never violence.
A34: 33 | B34: No | C34: G/2 — Ganesh · loyal-brave | D34: art/scenes/G/2.webp | E34: Use art/scenes/G/1.webp | F34: 3D animated cartoon style, like a Pixar-quality children's movie still: big expressive eyes, soft rounded shapes, warm cinematic lighting, rich saturated colours, vibrant Indian heritage setting (temples, forts, forests, palaces). Setting: a decorated entrance of a Kailash palace with flowers and lamps, soft light. Characters — Ganesh: child-friendly Lord Ganesh, elephant head with one tusk, big kind eyes, red-and-yellow dhoti, golden crown, round belly, four arms holding a modak, an axe, a lotus and a blessing hand, a small friendly mouse nearby. Action: the little boy (Ganesh as a child with a human face) stands at the door holding a small stick, arms spread, protecting the entrance. Expressions: serious, loyal, cute determination. Camera: front medium shot at his eye level. Landscape 16:9, 2816x1536 px. NO text, NO captions, NO letters, NO watermark, no logo. Child-friendly: no blood, no gore, no frightening faces. Battle scenes show only calm tension, never violence. Keep each character's face, hair, clothes and colours EXACTLY the same as in scene 1 of this story (use the scene 1 image as the reference image for every later scene).
A35: 34 | B35: No | C35: G/3 — Ganesh · surprised-blessing | D35: art/scenes/G/3.webp | E35: Use art/scenes/G/1.webp | F35: 3D animated cartoon style, like a Pixar-quality children's movie still: big expressive eyes, soft rounded shapes, warm cinematic lighting, rich saturated colours, vibrant Indian heritage setting (temples, forts, forests, palaces). Setting: Kailash palace courtyard with flower garlands and a glowing divine light. Characters — Shiva (Mahadev): Lord Shiva (Mahadev), pale blue-grey skin, matted hair with a crescent moon and the river Ganga flowing from it, a third eye, a serpent around the neck, tiger-skin cloth, a trident (trishul) and a damaru drum, calm meditative face. Ganesh: child-friendly Lord Ganesh, elephant head with one tusk, big kind eyes, red-and-yellow dhoti, golden crown, round belly, four arms holding a modak, an axe, a lotus and a blessing hand, a small friendly mouse nearby. Uma (Parvati): Goddess Parvati (Uma), fair golden-brown skin, red saree with a gold border, crown and flowers, a small bindi, peaceful loving face. Action: Lord Shiva places a gentle hand on the boy, who now has an elephant head and a happy smile; Parvati folds her hands with joy. Expressions: Shiva: kind and proud; Ganesh: delighted; Parvati: grateful tears of joy. Camera: medium shot with glowing light rays. Landscape 16:9, 2816x1536 px. NO text, NO captions, NO letters, NO watermark, no logo. Child-friendly: no blood, no gore, no frightening faces. Battle scenes show only calm tension, never violence. Keep each character's face, hair, clothes and colours EXACTLY the same as in scene 1 of this story (use the scene 1 image as the reference image for every later scene).
A36: 35 | B36: No | C36: G/4 — Ganesh · playful-sweet | D36: art/scenes/G/4.webp | E36: Use art/scenes/G/1.webp | F36: 3D animated cartoon style, like a Pixar-quality children's movie still: big expressive eyes, soft rounded shapes, warm cinematic lighting, rich saturated colours, vibrant Indian heritage setting (temples, forts, forests, palaces). Setting: a festive Ganesh Chaturthi room with flowers, marigold garlands, lamps and a plate of modaks. Characters — Ganesh: child-friendly Lord Ganesh, elephant head with one tusk, big kind eyes, red-and-yellow dhoti, golden crown, round belly, four arms holding a modak, an axe, a lotus and a blessing hand, a small friendly mouse nearby. Action: Ganesh sits on a lotus seat holding a modak in one hand while his small mouse friend nibbles a laddu beside him. Expressions: Ganesh: joyful, twinkling eyes; mouse: happy. Camera: close medium shot, warm festive glow. Landscape 16:9, 2816x1536 px. NO text, NO captions, NO letters, NO watermark, no logo. Child-friendly: no blood, no gore, no frightening faces. Battle scenes show only calm tension, never violence. Keep each character's face, hair, clothes and colours EXACTLY the same as in scene 1 of this story (use the scene 1 image as the reference image for every later scene).
A37: 36 | B37: No | C37: G/5 — Ganesh · wise-clever | D37: art/scenes/G/5.webp | E37: Use art/scenes/G/1.webp | F37: 3D animated cartoon style, like a Pixar-quality children's movie still: big expressive eyes, soft rounded shapes, warm cinematic lighting, rich saturated colours, vibrant Indian heritage setting (temples, forts, forests, palaces). Setting: Mount Kailash with snow peaks and a clear sky; a distant peacock with Kartikeya flying off in the background. Characters — Ganesh: child-friendly Lord Ganesh, elephant head with one tusk, big kind eyes, red-and-yellow dhoti, golden crown, round belly, four arms holding a modak, an axe, a lotus and a blessing hand, a small friendly mouse nearby. Shiva (Mahadev): Lord Shiva (Mahadev), pale blue-grey skin, matted hair with a crescent moon and the river Ganga flowing from it, a third eye, a serpent around the neck, tiger-skin cloth, a trident (trishul) and a damaru drum, calm meditative face. Uma (Parvati): Goddess Parvati (Uma), fair golden-brown skin, red saree with a gold border, crown and flowers, a small bindi, peaceful loving face. Action: Ganesh walks around his seated parents with folded hands, the mouse following; Shiva and Parvati smile warmly. Expressions: Ganesh: sweet and sure; Shiva and Parvati: proud. Camera: wide shot, golden light. Landscape 16:9, 2816x1536 px. NO text, NO captions, NO letters, NO watermark, no logo. Child-friendly: no blood, no gore, no frightening faces. Battle scenes show only calm tension, never violence. Keep each character's face, hair, clothes and colours EXACTLY the same as in scene 1 of this story (use the scene 1 image as the reference image for every later scene).
A38: 37 | B38: No | C38: H/1 — Hanuman · playful-curious | D38: art/scenes/H/1.webp | F38: 3D animated cartoon style, like a Pixar-quality children's movie still: big expressive eyes, soft rounded shapes, warm cinematic lighting, rich saturated colours, vibrant Indian heritage setting (temples, forts, forests, palaces). Setting: a glowing orange sky at sunrise over green hills, white clouds. Characters — Hanuman: mighty Hanuman with a golden-orange furry body and a monkey face, red mace (gada) on his shoulder, golden crown and earrings, red loincloth, long tail, kind devoted eyes. Action: baby Hanuman (a cute small monkey-boy with golden fur) flies up joyfully toward the big red sun, arms stretched, giggling. Expressions: wide-eyed joyful curiosity. Camera: low-angle wide shot with the sun glowing. Landscape 16:9, 2816x1536 px. NO text, NO captions, NO letters, NO watermark, no logo. Child-friendly: no blood, no gore, no frightening faces. Battle scenes show only calm tension, never violence.
A39: 38 | B39: No | C39: H/2 — Hanuman · blessed-gentle | D39: art/scenes/H/2.webp | E39: Use art/scenes/H/1.webp | F39: 3D animated cartoon style, like a Pixar-quality children's movie still: big expressive eyes, soft rounded shapes, warm cinematic lighting, rich saturated colours, vibrant Indian heritage setting (temples, forts, forests, palaces). Setting: heavenly clouds with golden light, divine gods gathering around. Characters — Hanuman: mighty Hanuman with a golden-orange furry body and a monkey face, red mace (gada) on his shoulder, golden crown and earrings, red loincloth, long tail, kind devoted eyes. Indra: king of the gods, golden crown, white and gold royal clothes, holds a golden thunderbolt (vajra), sits on the white four-tusked elephant Airavat. Action: little Hanuman sits calmly on a cloud while several gods including Indra bless him with raised hands and sparkles of light. Expressions: Hanuman: surprised then smiling; gods: kind and proud. Camera: wide celestial scene. Landscape 16:9, 2816x1536 px. NO text, NO captions, NO letters, NO watermark, no logo. Child-friendly: no blood, no gore, no frightening faces. Battle scenes show only calm tension, never violence. Keep each character's face, hair, clothes and colours EXACTLY the same as in scene 1 of this story (use the scene 1 image as the reference image for every later scene).
A40: 39 | B40: No | C40: H/3 — Hanuman · devoted-emotional | D40: art/scenes/H/3.webp | E40: Use art/scenes/H/1.webp | F40: 3D animated cartoon style, like a Pixar-quality children's movie still: big expressive eyes, soft rounded shapes, warm cinematic lighting, rich saturated colours, vibrant Indian heritage setting (temples, forts, forests, palaces). Setting: a rocky forest hill path in soft morning light. Characters — Hanuman: mighty Hanuman with a golden-orange furry body and a monkey face, red mace (gada) on his shoulder, golden crown and earrings, red loincloth, long tail, kind devoted eyes. Ram: blue-skinned Lord Ram, calm gentle smile, golden crown, saffron-yellow dhoti, a long bow, noble face. During exile: matted hair topknot and simple bark-cloth clothes. Laxman: young prince with golden-brown skin, hair in a topknot, simple yellow-green forest robes, a bow and quiver, alert loyal eyes. Action: Hanuman (disguised as a gentle young sage at first, then in his true form) bows with folded hands before Ram and Laxman, who smile warmly. Expressions: Hanuman: humble devotion; Ram: kind; Laxman: pleased. Camera: medium three-shot, warm light. Landscape 16:9, 2816x1536 px. NO text, NO captions, NO letters, NO watermark, no logo. Child-friendly: no blood, no gore, no frightening faces. Battle scenes show only calm tension, never violence. Keep each character's face, hair, clothes and colours EXACTLY the same as in scene 1 of this story (use the scene 1 image as the reference image for every later scene).
...

Sheet Gujarati Akshar
A1: # | B1: Done? | C1: Label | D1: Save as (file name) | E1: Reference first? | F1: Prompt (copy into Google Flow / Gemini)
A2: 1 | B2: No | C2: અ — Agni (sacred fire) | D2: art/items/akshar-gu/agni.webp | F2: 3D animated cartoon style, like a Pixar-quality children's movie still: big expressive eyes, soft rounded shapes, warm cinematic lighting, rich saturated colours, vibrant Indian heritage setting (temples, forts, forests, palaces). Subject: a calm sacred fire with golden flames rising from a brass fire-pit. Setting: a simple yajna ground at dawn with flowers and a ghee pot. Composition for a single-subject picture: one clear hero subject in the centre, simple uncluttered background so a small child recognises it at a glance, joyful and welcoming mood. Landscape 16:9, 2816x1536 px. NO text, NO captions, NO letters, NO watermark, no logo. Child-friendly: no blood, no gore, no frightening faces. Battle scenes show only calm tension, never violence.
A3: 2 | B3: No | C3: આ — Aarti | D3: art/items/akshar-gu/aarti.webp | F3: 3D animated cartoon style, like a Pixar-quality children's movie still: big expressive eyes, soft rounded shapes, warm cinematic lighting, rich saturated colours, vibrant Indian heritage setting (temples, forts, forests, palaces). Subject: a hand waving a lit aarti plate with a diya, flowers and incense. Setting: a cosy home temple corner in the evening. Composition for a single-subject picture: one clear hero subject in the centre, simple uncluttered background so a small child recognises it at a glance, joyful and welcoming mood. Landscape 16:9, 2816x1536 px. NO text, NO captions, NO letters, NO watermark, no logo. Child-friendly: no blood, no gore, no frightening faces. Battle scenes show only calm tension, never violence.
A4: 3 | B4: No | C4: ઇ — King Ikshvaku | D4: art/items/akshar-gu/ikshvaku.webp | F4: 3D animated cartoon style, like a Pixar-quality children's movie still: big expressive eyes, soft rounded shapes, warm cinematic lighting, rich saturated colours, vibrant Indian heritage setting (temples, forts, forests, palaces). Subject: a kind ancient king in a golden crown with a sun symbol on his chest. Setting: a royal garden with a glowing sun rising behind a palace. Composition for a single-subject picture: one clear hero subject in the centre, simple uncluttered background so a small child recognises it at a glance, joyful and welcoming mood. Landscape 16:9, 2816x1536 px. NO text, NO captions, NO letters, NO watermark, no logo. Child-friendly: no blood, no gore, no frightening faces. Battle scenes show only calm tension, never violence.
